[2024-03-03T01:41:07.740+0000] {taskinstance.py:1979} INFO - Dependencies all met for dep_context=non-requeueable deps ti=<TaskInstance: stock_analyzer.calculate_delta manual__2024-03-03T01:40:57.641629+00:00 [queued]>
[2024-03-03T01:41:07.747+0000] {taskinstance.py:1979} INFO - Dependencies all met for dep_context=requeueable deps ti=<TaskInstance: stock_analyzer.calculate_delta manual__2024-03-03T01:40:57.641629+00:00 [queued]>
[2024-03-03T01:41:07.747+0000] {taskinstance.py:2193} INFO - Starting attempt 1 of 1
[2024-03-03T01:41:07.764+0000] {taskinstance.py:2214} INFO - Executing <Task(_PythonDecoratedOperator): calculate_delta> on 2024-03-03 01:40:57.641629+00:00
[2024-03-03T01:41:07.772+0000] {standard_task_runner.py:60} INFO - Started process 1399 to run task
[2024-03-03T01:41:07.775+0000] {standard_task_runner.py:87} INFO - Running: ['***', 'tasks', 'run', 'stock_analyzer', 'calculate_delta', 'manual__2024-03-03T01:40:57.641629+00:00', '--job-id', '251', '--raw', '--subdir', 'DAGS_FOLDER/stock-analyzer.py', '--cfg-path', '/tmp/tmpg9vwye38']
[2024-03-03T01:41:07.777+0000] {standard_task_runner.py:88} INFO - Job 251: Subtask calculate_delta
[2024-03-03T01:41:07.815+0000] {task_command.py:423} INFO - Running <TaskInstance: stock_analyzer.calculate_delta manual__2024-03-03T01:40:57.641629+00:00 [running]> on host 0a26efe0197d
[2024-03-03T01:41:07.890+0000] {taskinstance.py:2510} INFO - Exporting env vars: AIRFLOW_CTX_DAG_OWNER='root' AIRFLOW_CTX_DAG_ID='stock_analyzer' AIRFLOW_CTX_TASK_ID='calculate_delta' AIRFLOW_CTX_EXECUTION_DATE='2024-03-03T01:40:57.641629+00:00' AIRFLOW_CTX_TRY_NUMBER='1' AIRFLOW_CTX_DAG_RUN_ID='manual__2024-03-03T01:40:57.641629+00:00'
[2024-03-03T01:41:07.911+0000] {taskinstance.py:2728} ERROR - Task failed with exception
Traceback (most recent call last):
  File "/home/airflow/.local/lib/python3.11/site-packages/airflow/models/taskinstance.py", line 444, in _execute_task
    result = _execute_callable(context=context, **execute_callable_kwargs)
             ^^^^^^^^^^^^^^^^^^^^^^^^^^^^^^^^^^^^^^^^^^^^^^^^^^^^^^^^^^^^^
  File "/home/airflow/.local/lib/python3.11/site-packages/airflow/models/taskinstance.py", line 414, in _execute_callable
    return execute_callable(context=context, **execute_callable_kwargs)
           ^^^^^^^^^^^^^^^^^^^^^^^^^^^^^^^^^^^^^^^^^^^^^^^^^^^^^^^^^^^^
  File "/home/airflow/.local/lib/python3.11/site-packages/airflow/decorators/base.py", line 241, in execute
    return_value = super().execute(context)
                   ^^^^^^^^^^^^^^^^^^^^^^^^
  File "/home/airflow/.local/lib/python3.11/site-packages/airflow/operators/python.py", line 200, in execute
    return_value = self.execute_callable()
                   ^^^^^^^^^^^^^^^^^^^^^^^
  File "/home/airflow/.local/lib/python3.11/site-packages/airflow/operators/python.py", line 217, in execute_callable
    return self.python_callable(*self.op_args, **self.op_kwargs)
           ^^^^^^^^^^^^^^^^^^^^^^^^^^^^^^^^^^^^^^^^^^^^^^^^^^^^^
  File "/opt/airflow/dags/stock-analyzer.py", line 70, in calculate_delta
    if not os.file_exists(delta_file):
           ^^^^^^^^^^^^^^
AttributeError: module 'os' has no attribute 'file_exists'
[2024-03-03T01:41:07.919+0000] {taskinstance.py:1149} INFO - Marking task as FAILED. dag_id=stock_analyzer, task_id=calculate_delta, execution_date=20240303T014057, start_date=20240303T014107, end_date=20240303T014107
[2024-03-03T01:41:07.934+0000] {standard_task_runner.py:107} ERROR - Failed to execute job 251 for task calculate_delta (module 'os' has no attribute 'file_exists'; 1399)
[2024-03-03T01:41:07.988+0000] {local_task_job_runner.py:234} INFO - Task exited with return code 1
[2024-03-03T01:41:08.006+0000] {taskinstance.py:3309} INFO - 0 downstream tasks scheduled from follow-on schedule check
