[2024-02-29T06:06:39.293+0000] {taskinstance.py:1979} INFO - Dependencies all met for dep_context=non-requeueable deps ti=<TaskInstance: fetch_data.call_api_and_save_response__1 manual__2024-02-29T06:06:37.333171+00:00 [queued]>
[2024-02-29T06:06:39.300+0000] {taskinstance.py:1979} INFO - Dependencies all met for dep_context=requeueable deps ti=<TaskInstance: fetch_data.call_api_and_save_response__1 manual__2024-02-29T06:06:37.333171+00:00 [queued]>
[2024-02-29T06:06:39.300+0000] {taskinstance.py:2193} INFO - Starting attempt 1 of 1
[2024-02-29T06:06:39.321+0000] {taskinstance.py:2214} INFO - Executing <Task(_PythonDecoratedOperator): call_api_and_save_response__1> on 2024-02-29 06:06:37.333171+00:00
[2024-02-29T06:06:39.328+0000] {standard_task_runner.py:60} INFO - Started process 57 to run task
[2024-02-29T06:06:39.333+0000] {standard_task_runner.py:87} INFO - Running: ['***', 'tasks', 'run', 'fetch_data', 'call_api_and_save_response__1', 'manual__2024-02-29T06:06:37.333171+00:00', '--job-id', '26', '--raw', '--subdir', 'DAGS_FOLDER/fetch_data.py', '--cfg-path', '/tmp/tmp2ltcdtpt']
[2024-02-29T06:06:39.334+0000] {standard_task_runner.py:88} INFO - Job 26: Subtask call_api_and_save_response__1
[2024-02-29T06:06:39.393+0000] {task_command.py:423} INFO - Running <TaskInstance: fetch_data.call_api_and_save_response__1 manual__2024-02-29T06:06:37.333171+00:00 [running]> on host 0a26efe0197d
[2024-02-29T06:06:39.514+0000] {taskinstance.py:2510} INFO - Exporting env vars: AIRFLOW_CTX_DAG_OWNER='root' AIRFLOW_CTX_DAG_ID='fetch_data' AIRFLOW_CTX_TASK_ID='call_api_and_save_response__1' AIRFLOW_CTX_EXECUTION_DATE='2024-02-29T06:06:37.333171+00:00' AIRFLOW_CTX_TRY_NUMBER='1' AIRFLOW_CTX_DAG_RUN_ID='manual__2024-02-29T06:06:37.333171+00:00'
[2024-02-29T06:06:40.165+0000] {taskinstance.py:2728} ERROR - Task failed with exception
Traceback (most recent call last):
  File "/home/airflow/.local/lib/python3.11/site-packages/airflow/models/taskinstance.py", line 444, in _execute_task
    result = _execute_callable(context=context, **execute_callable_kwargs)
             ^^^^^^^^^^^^^^^^^^^^^^^^^^^^^^^^^^^^^^^^^^^^^^^^^^^^^^^^^^^^^
  File "/home/airflow/.local/lib/python3.11/site-packages/airflow/models/taskinstance.py", line 414, in _execute_callable
    return execute_callable(context=context, **execute_callable_kwargs)
           ^^^^^^^^^^^^^^^^^^^^^^^^^^^^^^^^^^^^^^^^^^^^^^^^^^^^^^^^^^^^
  File "/home/airflow/.local/lib/python3.11/site-packages/airflow/decorators/base.py", line 241, in execute
    return_value = super().execute(context)
                   ^^^^^^^^^^^^^^^^^^^^^^^^
  File "/home/airflow/.local/lib/python3.11/site-packages/airflow/operators/python.py", line 200, in execute
    return_value = self.execute_callable()
                   ^^^^^^^^^^^^^^^^^^^^^^^
  File "/home/airflow/.local/lib/python3.11/site-packages/airflow/operators/python.py", line 217, in execute_callable
    return self.python_callable(*self.op_args, **self.op_kwargs)
           ^^^^^^^^^^^^^^^^^^^^^^^^^^^^^^^^^^^^^^^^^^^^^^^^^^^^^
  File "/opt/airflow/dags/fetch_data.py", line 28, in call_api_and_save_response
    with open(output_file, 'w') as f:
         ^^^^^^^^^^^^^^^^^^^^^^
FileNotFoundError: [Errno 2] No such file or directory: '../data/irctc_data.json'
[2024-02-29T06:06:40.186+0000] {taskinstance.py:1149} INFO - Marking task as FAILED. dag_id=fetch_data, task_id=call_api_and_save_response__1, execution_date=20240229T060637, start_date=20240229T060639, end_date=20240229T060640
[2024-02-29T06:06:40.247+0000] {standard_task_runner.py:107} ERROR - Failed to execute job 26 for task call_api_and_save_response__1 ([Errno 2] No such file or directory: '../data/irctc_data.json'; 57)
[2024-02-29T06:06:40.329+0000] {local_task_job_runner.py:234} INFO - Task exited with return code 1
[2024-02-29T06:06:40.374+0000] {taskinstance.py:3309} INFO - 0 downstream tasks scheduled from follow-on schedule check
